<?xml version="1.0" encoding="utf-8"?>
<!-- This URDF was automatically created by SolidWorks to URDF Exporter! Originally created by Stephen Brawner (brawner@gmail.com) 
     Commit Version: 1.5.1-0-g916b5db  Build Version: 1.5.7152.31018
     For more information, please see http://wiki.ros.org/sw_urdf_exporter -->
<robot
  name="mbot_description">
  <link
    name="base_link">
    <inertial>
      <origin
        xyz="0.0094982 0.0002258 0.046754"
        rpy="0 0 0" />
      <mass
        value="0.7" />
      <inertia
        ixx="0.034352"
        ixy="4.6068E-05"
        ixz="9.4492E-05"
        iyy="0.033935"
        iyz="-4.3761E-05"
        izz="0.065023" />
    </inertial>
    <visual>
      <origin
        xyz="0 0 0"
        rpy="0 0 0" />
      <geometry>
        <mesh
          filename="package://mbot_description/meshes/base_link.STL" />
      </geometry>
      <material
        name="">
        <color
          rgba="0.79216 0.81961 0.93333 1" />
      </material>
    </visual>
    <collision>
      <origin
        xyz="0 0 0"
        rpy="0 0 0" />
      <geometry>
        <mesh
          filename="package://mbot_description/meshes/base_link.STL" />
      </geometry>
    </collision>
  </link>
  <link
    name="left_front_wheel_link">
    <inertial>
      <origin
        xyz="4.1183E-07 0.021379 -5.7842E-07"
        rpy="0 0 0" />
      <mass
        value="0.7" />
      <inertia
        ixx="1.4395E-05"
        ixy="1.555E-16"
        ixz="2.9721E-14"
        iyy="2.6335E-05"
        iyz="1.4595E-14"
        izz="1.4395E-05" />
    </inertial>
    <visual>
      <origin
        xyz="0 0 0"
        rpy="0 0 0" />
      <geometry>
        <mesh
          filename="package://mbot_description/meshes/left_front_wheel_link.STL" />
      </geometry>
      <material
        name="">
        <color
          rgba="0.79216 0.81961 0.93333 1" />
      </material>
    </visual>
    <collision>
      <origin
        xyz="0 0 0"
        rpy="0 0 0" />
      <geometry>
        <mesh
          filename="package://mbot_description/meshes/left_front_wheel_link.STL" />
      </geometry>
    </collision>
  </link>
  <joint
    name="left_front_wheel_joint"
    type="continuous">
    <origin
      xyz="0.148886114908057 0.118004510146033 -0.0935321635431457"
      rpy="0 0 0" />
    <parent
      link="base_link" />
    <child
      link="left_front_wheel_link" />
    <axis
      xyz="0 1 0" />
  </joint>
  <link
    name="left_back_wheel_link">
    <inertial>
      <origin
        xyz="8.7387E-07 0.021379 9.4971E-07"
        rpy="0 0 0" />
      <mass
        value="0.7" />
      <inertia
        ixx="1.4388E-05"
        ixy="-4.0164E-12"
        ixz="-4.9942E-10"
        iyy="2.6318E-05"
        iyz="6.5432E-13"
        izz="1.4385E-05" />
    </inertial>
    <visual>
      <origin
        xyz="0 0 0"
        rpy="0 0 0" />
      <geometry>
        <mesh
          filename="package://mbot_description/meshes/left_back_wheel_link.STL" />
      </geometry>
      <material
        name="">
        <color
          rgba="0.79216 0.81961 0.93333 1" />
      </material>
    </visual>
    <collision>
      <origin
        xyz="0 0 0"
        rpy="0 0 0" />
      <geometry>
        <mesh
          filename="package://mbot_description/meshes/left_back_wheel_link.STL" />
      </geometry>
    </collision>
  </link>
  <joint
    name="left_back_wheel_joint"
    type="continuous">
    <origin
      xyz="-0.148886114908084 0.118004510146055 -0.0935321635431195"
      rpy="0 0 0" />
    <parent
      link="base_link" />
    <child
      link="left_back_wheel_link" />
    <axis
      xyz="0 1 0" />
  </joint>
  <link
    name="right_front_wheel_link">
    <inertial>
      <origin
        xyz="-1.1614E-06 -0.021379 5.6288E-07"
        rpy="0 0 0" />
      <mass
        value="0.7" />
      <inertia
        ixx="1.4387E-05"
        ixy="-3.4962E-12"
        ixz="1.3835E-09"
        iyy="2.6318E-05"
        iyz="-2.0822E-12"
        izz="1.4386E-05" />
    </inertial>
    <visual>
      <origin
        xyz="0 0 0"
        rpy="0 0 0" />
      <geometry>
        <mesh
          filename="package://mbot_description/meshes/right_front_wheel_link.STL" />
      </geometry>
      <material
        name="">
        <color
          rgba="0.79216 0.81961 0.93333 1" />
      </material>
    </visual>
    <collision>
      <origin
        xyz="0 0 0"
        rpy="0 0 0" />
      <geometry>
        <mesh
          filename="package://mbot_description/meshes/right_front_wheel_link.STL" />
      </geometry>
    </collision>
  </link>
  <joint
    name="right_front_wheel_joint"
    type="continuous">
    <origin
      xyz="0.148886114908022 -0.118004510146034 -0.0935321635431398"
      rpy="0 0 0" />
    <parent
      link="base_link" />
    <child
      link="right_front_wheel_link" />
    <axis
      xyz="0 1 0" />
  </joint>
  <link
    name="right_back_wheel_link">
    <inertial>
      <origin
        xyz="6.1199E-07 -0.021379 -3.6005E-07"
        rpy="0 0 0" />
      <mass
        value="0.7" />
      <inertia
        ixx="1.4395E-05"
        ixy="1.453E-14"
        ixz="2.7878E-13"
        iyy="2.6335E-05"
        iyz="1.4143E-15"
        izz="1.4395E-05" />
    </inertial>
    <visual>
      <origin
        xyz="0 0 0"
        rpy="0 0 0" />
      <geometry>
        <mesh
          filename="package://mbot_description/meshes/right_back_wheel_link.STL" />
      </geometry>
      <material
        name="">
        <color
          rgba="0.79216 0.81961 0.93333 1" />
      </material>
    </visual>
    <collision>
      <origin
        xyz="0 0 0"
        rpy="0 0 0" />
      <geometry>
        <mesh
          filename="package://mbot_description/meshes/right_back_wheel_link.STL" />
      </geometry>
    </collision>
  </link>
  <joint
    name="right_back_wheel_joint"
    type="continuous">
    <origin
      xyz="-0.148886114908137 -0.118004510146062 -0.0935321635431195"
      rpy="0 0 0" />
    <parent
      link="base_link" />
    <child
      link="right_back_wheel_link" />
    <axis
      xyz="0 1 0" />
  </joint>
  <link
    name="laser_radar_link">
    <inertial>
      <origin
        xyz="-0.010456 -8.5828E-05 -0.028228"
        rpy="0 0 0" />
      <mass
        value="0.13545" />
      <inertia
        ixx="3.0354E-05"
        ixy="-1.1384E-07"
        ixz="-1.0946E-08"
        iyy="3.9719E-05"
        iyz="-1.336E-10"
        izz="6.0734E-05" />
    </inertial>
    <visual>
      <origin
        xyz="0 0 0"
        rpy="0 0 0" />
      <geometry>
        <mesh
          filename="package://mbot_description/meshes/laser_radar_link.STL" />
      </geometry>
      <material
        name="">
        <color
          rgba="0.64706 0.51765 0 1" />
      </material>
    </visual>
    <collision>
      <origin
        xyz="0 0 0"
        rpy="0 0 0" />
      <geometry>
        <mesh
          filename="package://mbot_description/meshes/laser_radar_link.STL" />
      </geometry>
    </collision>
  </link>
  <joint
    name="laser_radar_joint"
    type="fixed">
    <origin
      xyz="0.0606898374226744 -0.00398486346124755 0.183"
      rpy="0 0 0" />
    <parent
      link="base_link" />
    <child
      link="laser_radar_link" />
    <axis
      xyz="0 0 0" />
  </joint>
  <link
    name="flag_link">
    <inertial>
      <origin
        xyz="0.0066748 -0.0030085 -0.012975"
        rpy="0 0 0" />
      <mass
        value="0.021395" />
      <inertia
        ixx="2.6682E-05"
        ixy="2.1481E-09"
        ixz="7.5692E-06"
        iyy="3.6559E-05"
        iyz="4.174E-09"
        izz="9.999E-06" />
    </inertial>
    <visual>
      <origin
        xyz="0 0 0"
        rpy="0 0 0" />
      <geometry>
        <mesh
          filename="package://mbot_description/meshes/flag_link.STL" />
      </geometry>
      <material
        name="">
        <color
          rgba="1 1 1 1" />
      </material>
    </visual>
    <collision>
      <origin
        xyz="0 0 0"
        rpy="0 0 0" />
      <geometry>
        <mesh
          filename="package://mbot_description/meshes/flag_link.STL" />
      </geometry>
    </collision>
  </link>
  <joint
    name="flag_joint"
    type="fixed">
    <origin
      xyz="-0.142157420945777 -0.118756232223705 0.227749122572869"
      rpy="0 0 0" />
    <parent
      link="base_link" />
    <child
      link="flag_link" />
    <axis
      xyz="0 0 0" />
  </joint>


  <link name="base_footprint"></link>
  <joint name="base_footprint_joint" type="fixed">
    <parent link="base_footprint" />
    <child link="base_link" />
  </joint>

  <!-- <transmission name="driving_wheel_left_trans">
    <type>transmission_interface/SimpleTransmission</type>
    <joint name="driving_wheel_left_Joint">
      <hardwareInterface>hardware_interface/VelocityJointInterface</hardwareInterface>
    </joint>
    <actuator name="driving_wheel_left_motor">
      <hardwareInterface>hardware_interface/VelocityJointInterface</hardwareInterface>
      <mechanicalReduction>1</mechanicalReduction>
    </actuator>
  </transmission>

  <transmission name="driving_wheel_right_trans">
    <type>transmission_interface/SimpleTransmission</type>
    <joint name="driving_wheel_right_Joint">
      <hardwareInterface>hardware_interface/VelocityJointInterface</hardwareInterface>
    </joint>
    <actuator name="driving_wheel_right_motor">
      <hardwareInterface>hardware_interface/VelocityJointInterface</hardwareInterface>
      <mechanicalReduction>1</mechanicalReduction>
    </actuator>
  </transmission> -->


  <!-- <gazebo>
    <plugin name="skid_steer_drive_controller" filename="libgazebo_ros_skid_steer_drive.so">
      <updateRate>100.0</updateRate>
      <robotNamespace>/</robotNamespace>
      <leftFrontJoint>left_front_wheel_joint</leftFrontJoint>
      <rightFrontJoint>right_front_wheel_joint</rightFrontJoint>
      <leftRearJoint>left_back_wheel_joint</leftRearJoint>
      <rightRearJoint>right_back_wheel_joint</rightRearJoint>
      <wheelSeparation>0.32</wheelSeparation>
      <wheelDiameter>0.09</wheelDiameter>
      <robotBaseFrame>base_link</robotBaseFrame>
      <torque>20</torque>
      <topicName>cmd_vel</topicName>
      <broadcastTF>false</broadcastTF>
    </plugin>
  </gazebo> -->

  <gazebo>
    <plugin name="differential_drive_controller" filename="libgazebo_ros_diff_drive.so">
      <rosDebugLevel>Debug</rosDebugLevel>
      <publishWheelTF>ture</publishWheelTF>
      <robotNamespace>/</robotNamespace>
      <publishTf>1</publishTf>
      <publishWheelJointState>true</publishWheelJointState>
      <alwaysOn>true</alwaysOn>
      <updateRate>100.0</updateRate>
      <legacyMode>true</legacyMode>
      <leftJoint>left_front_wheel_joint</leftJoint>
      <rightJoint>right_front_wheel_joint</rightJoint>
      <wheelSeparation>0.45</wheelSeparation>
      <wheelDiameter>0.03</wheelDiameter>
      <broadcastTF>1</broadcastTF>
      <wheelTorque>100</wheelTorque>
      <wheelAcceleration>1.8</wheelAcceleration>
      <commandTopic>cmd_vel</commandTopic>
      <odometryFrame>odom</odometryFrame>
      <odometryTopic>odom</odometryTopic>
      <robotBaseFrame>base_footprint</robotBaseFrame>
      <odometrySource>world</odometrySource>
      <publishTf>1</publishTf>
    </plugin>
  </gazebo>

  <gazebo>
    <plugin name="differential_drive_controller" filename="libgazebo_ros_diff_drive.so">
      <rosDebugLevel>Debug</rosDebugLevel>
      <publishWheelTF>true</publishWheelTF>
      <robotNamespace>/</robotNamespace>
      <publishTf>1</publishTf>
      <publishWheelJointState>true</publishWheelJointState>
      <alwaysOn>true</alwaysOn>
      <updateRate>100.0</updateRate>
      <legacyMode>true</legacyMode>
      <leftJoint>left_back_wheel_joint</leftJoint>
      <rightJoint>right_back_wheel_joint</rightJoint>
      <wheelSeparation>0.45</wheelSeparation>
      <wheelDiameter>0.03</wheelDiameter>
      <broadcastTF>1</broadcastTF>
      <wheelTorque>100</wheelTorque>
      <wheelAcceleration>1.8</wheelAcceleration>
      <commandTopic>cmd_vel</commandTopic>
      <odometryFrame>odom</odometryFrame>
      <odometryTopic>odom</odometryTopic>
      <robotBaseFrame>base_footprint</robotBaseFrame>
      <odometrySource>world</odometrySource>
      <publishTf>1</publishTf>
    </plugin>
  </gazebo>



  <gazebo reference="laser_radar_link">
    <sensor type="ray" name="rplidar">
      <pose>0 0 0 0 0 0</pose>
      <visualize>false</visualize>
      <update_rate>5.5</update_rate>
      <ray>
        <scan>
          <horizontal>
            <samples>360</samples>
            <resolution>1</resolution>
            <min_angle>-3</min_angle>
            <max_angle>3</max_angle>
          </horizontal>
        </scan>
        <range>
          <min>0.10</min>
          <max>6.0</max>
          <resolution>0.01</resolution>
        </range>
        <noise>
          <type>gaussian</type>
          <mean>0.0</mean>
          <stddev>0.01</stddev>
        </noise>
      </ray>
      <plugin name="gazebo_rplidar" filename="libgazebo_ros_laser.so">
        <topicName>/scan</topicName>
        <frameName>laser_radar_link</frameName>
      </plugin>
    </sensor>
  </gazebo>


  <gazebo reference="base_link">
    <material>Gazebo/Grey</material>
  </gazebo>

 <gazebo reference="laser_radar_link">
    <material>Gazebo/DarkGrey
    </material>
  </gazebo>

  <gazebo reference="flag_link">
    <material>Gazebo/Red</material>
  </gazebo>
  
  <gazebo reference="left_front_wheel_link">
    <mu1>10000000</mu1>
    <mu2>10000000</mu2>
    <kp>500000.0</kp>
    <kd>10.0</kd>
    <minDepth>0.001</minDepth>
    <maxVel>0.1</maxVel>
    <fdir1>1 0 0</fdir1>
    <material>Gazebo/Yellow</material>
  </gazebo>

  <gazebo reference="left_back_wheel_link">
    <mu1>10000000</mu1>
    <mu2>10000000</mu2>
    <kp>500000.0</kp>
    <kd>10.0</kd>
    <minDepth>0.001</minDepth>
    <maxVel>0.1</maxVel>
    <fdir1>1 0 0</fdir1>
    <material>Gazebo/Yellow</material>
  </gazebo>

  <gazebo reference="right_front_wheel_link">
    <mu1>10000000</mu1>
    <mu2>10000000</mu2>
    <kp>500000.0</kp>
    <kd>10.0</kd>
    <minDepth>0.001</minDepth>
    <maxVel>0.1</maxVel>
    <fdir1>1 0 0</fdir1>
    <material>Gazebo/Yellow</material>
  </gazebo>

  <gazebo reference="right_back_wheel_link">
    <mu1>10000000</mu1>
    <mu2>10000000</mu2>
    <kp>500000.0</kp>
    <kd>10.0</kd>
    <minDepth>0.001</minDepth>
    <maxVel>0.1</maxVel>
    <fdir1>1 0 0</fdir1>
    <material>Gazebo/Yellow</material>
  </gazebo>
  
</robot>